<?xml version="1.0"?>

<xacro xmlns:xacro="http://www.ros.org/wiki/xacro">

    <xacro:property name="PI" value="3.1415926535897931"/>

    <!-- Body properties -->
    <xacro:property name="front_body_mass" value="0.5"/>
    <xacro:property name="back_body_mass" value="2"/>
    <xacro:property name="middle_body_mass" value="2"/>
    <xacro:property name="back_water_displaced_mass" value="10"/>
    <xacro:property name="middle_water_displaced_mass" value="10"/>
    <xacro:property name="front_water_displaced_mass" value="5"/>
    <xacro:property name="scale" value="0.21"/>
    <xacro:property name="bl1" value=".1" />
    <xacro:property name="bl2" value=".1" />
    
    

    <link name="base_link">
        <visual>
          <origin rpy="0 0 0" xyz="0 0 0"/>
          <geometry>
            <mesh filename="package://usv_sim/meshes/simpleHull3/base_link.dae" scale="${scale} ${scale} ${scale}"/>
          </geometry>
        </visual>
        <collision>
          <origin rpy="0 0 0" xyz="0 0 0"/>
          <geometry>
            <mesh filename="package://usv_sim/meshes/simpleHull3/base_link.dae" scale="${scale} ${scale} ${scale}"/>
          </geometry>
        </collision>

        <inertial>
            <origin rpy="0 0 0" xyz="${0.35*scale} ${0.44*scale} ${-0.2*scale}"/>
          <mass value="${middle_body_mass+extraPayload/2}"/>
          <inertia ixx="0.1" ixy="0.0" ixz="0.0" iyy="1.4" iyz="0.0" izz="1.4"/>
        </inertial>
        <buoyancy>
			<compensation>${middle_water_displaced_mass/middle_body_mass}</compensation>
			<origin xyz="${0.35*scale} ${0.44*scale} ${-0.15*scale}"/>
			<limit radius="0.1"/>
			<damping rpy="${angularDampingXYZ}" xyz="${dampingXYZ}"/>
         	<windVelocity>${windType}</windVelocity>
			<frontal_area>0.0</frontal_area>
			<lateral_area>0.012</lateral_area>
			<lateral_length>1.06</lateral_length>
	  		<waterVelocity>${waterType}</waterVelocity>
        </buoyancy>
    </link>


    
    
    <link name="center_r_link">
    	<visual>
          <origin rpy="0 0 0"  xyz="0 0 ${0*scale}"/>
          <geometry>
            <mesh filename="package://usv_sim/meshes/simpleHull3/centerRight.dae" scale="${scale} ${scale} ${scale}"/>
          </geometry>
        </visual>
        
        <collision>
          <origin rpy="0 0 0"  xyz="0 0 ${0*scale}"/>
          <geometry>
           	<mesh filename="package://usv_sim/meshes/simpleHull3/centerRight.dae" scale="${scale} ${scale} ${scale}"/>
          </geometry>
        </collision>

        <inertial>
            <origin rpy="0 0 0" xyz="${0.35*scale} ${-0.44*scale} ${-0.2*scale}"/>
          <mass value="${middle_body_mass+extraPayload/2}"/>
          <inertia ixx="0.1" ixy="0.0" ixz="0.0" iyy="1.4" iyz="0.0" izz="1.4"/>
        </inertial>
        <buoyancy>
          <compensation>${middle_water_displaced_mass/middle_body_mass}</compensation>
          <origin xyz="${0.35*scale} ${-0.44*scale} ${-0.15*scale}"/>
          <limit radius="0.1"/>
          <damping rpy="${angularDampingXYZ}" xyz="${dampingXYZ}"/>
			<windVelocity>${windType}</windVelocity>
			<frontal_area>0.0</frontal_area>
			<lateral_area>0.012</lateral_area>
			<lateral_length>1.06</lateral_length>
	  <waterVelocity>${waterType}</waterVelocity>
        </buoyancy>
    </link>

    <joint name="center_r_joint" type="revolute">
        <parent link="base_link"/>
        <child link="center_r_link"/>
        <origin rpy="0 0 0" xyz="0 0 0"/>
	<limit effort="50" velocity="5" lower="0" upper="0" />
            <dynamics damping="1.0"/>
            <axis xyz="1 0 0"/>
    </joint>


    <link name="back_l_link">
        <visual>
          <origin rpy="0 0 0"  xyz="0 0 0"/>
          <geometry>
           	<mesh filename="package://usv_sim/meshes/simpleHull3/backLeft.dae" scale="${scale} ${scale} ${scale}"/>
          </geometry>
        </visual>
        <collision>
          <origin rpy="0 0 0"  xyz="0 0 0"/>
          <geometry>
           	<mesh filename="package://usv_sim/meshes/simpleHull3/backLeft.dae" scale="${scale} ${scale} ${scale}"/>
          </geometry>
        </collision>

        <inertial>
            <origin rpy="0 0 0" xyz="${-0.6*scale} 0 ${-0.2*scale}"/>
          <mass value="${back_body_mass}"/>
          <inertia ixx="0.1" ixy="0.0" ixz="0.0" iyy="1.4" iyz="0.0" izz="1.4"/>
        </inertial>
        <buoyancy>
			<compensation>${back_water_displaced_mass/back_body_mass}</compensation>
			<origin xyz="${-0.6*scale} 0 ${-0.15*scale}"/>
			<limit radius="0.1"/>
			<damping rpy="${angularDampingXYZ}" xyz="${dampingXYZ}"/>
			<windVelocity>${windType}</windVelocity>
			<frontal_area>0.02</frontal_area>
			<lateral_area>0.012</lateral_area>
			<lateral_length>1.06</lateral_length>
	  		<waterVelocity>${waterType}</waterVelocity>
        </buoyancy>
    </link>

    <joint name="back_l_joint" type="revolute">
        <parent link="base_link"/>
        <child link="back_l_link"/>
        <origin rpy="0 0 0" xyz="${-0.5*scale} ${0.39*scale} 0"/>
	<limit effort="50" velocity="5" lower="0" upper="0" />
            <dynamics damping="1.0"/>
            <axis xyz="1 0 0"/>
    </joint>

    <link name="back_r_link">
    	<visual>
          <origin rpy="0 0 0"  xyz="0 0 0"/>
          <geometry>
           	<mesh filename="package://usv_sim/meshes/simpleHull3/backRight.dae" scale="${scale} ${scale} ${scale}"/>
          </geometry>
    	</visual>
        <collision>
          <origin rpy="0 0 0"  xyz="0 0 0"/>
          <geometry>
           	<mesh filename="package://usv_sim/meshes/simpleHull3/backRight.dae" scale="${scale} ${scale} ${scale}"/>
          </geometry>
        </collision>

        <inertial>
            <origin rpy="0 0 0" xyz="${-0.6*scale} 0 ${-0.2*scale}"/>
          <mass value="${back_body_mass}"/>
          <inertia ixx="0.1" ixy="0.0" ixz="0.0" iyy="1.4" iyz="0.0" izz="1.4"/>
        </inertial>
        <buoyancy>
          	<compensation>${back_water_displaced_mass/back_body_mass}</compensation>
          	<origin xyz="${-0.6*scale} 0 ${-0.15*scale}"/>
          	<limit radius="0.1"/>
          	<damping rpy="${angularDampingXYZ}" xyz="${dampingXYZ}"/>
          	<windVelocity>${windType}</windVelocity>
			<frontal_area>0.02</frontal_area>
			<lateral_area>0.012</lateral_area>
			<lateral_length>1.06</lateral_length>
	  		<waterVelocity>${waterType}</waterVelocity>
        </buoyancy>
    </link>

    <joint name="back_r_joint" type="revolute">
        <parent link="base_link"/>
        <child link="back_r_link"/>
        <origin rpy="0 0 0" xyz="${-0.5*scale} ${-0.39*scale} 0"/>
	<limit effort="50" velocity="5" lower="0" upper="0" />
            <dynamics damping="1.0"/>
            <axis xyz="1 0 0"/>
    </joint>


    <link name="front_l_link">
    	<visual>
    	<origin rpy="0 0 0"  xyz="0 0 0"/>
          <geometry>
           	<mesh filename="package://usv_sim/meshes/simpleHull3/frontLeft.dae" scale="${scale} ${scale} ${scale}"/>
          </geometry>
    	</visual>
        <collision>
          <origin rpy="0 0 0"  xyz="0 0 0"/>
          <geometry>
           	<mesh filename="package://usv_sim/meshes/simpleHull3/frontLeft.dae" scale="${scale} ${scale} ${scale}"/>
          </geometry>
        </collision>

        <inertial>
            <origin rpy="0 0 0" xyz="${0.4*scale} 0 ${-0.1*scale}"/>
          <mass value="${front_body_mass}"/>
          <inertia ixx="0.1" ixy="0.0" ixz="0.0" iyy="1.4" iyz="0.0" izz="1.4"/>
        </inertial>
        <buoyancy>
          	<compensation>${front_water_displaced_mass/front_body_mass}</compensation>
          	<origin xyz="${0.4*scale} 0 ${-0.05*scale}"/>
          	<limit radius="0.1"/>
          	<damping rpy="${angularDampingXYZ}" xyz="${dampingXYZ}"/>
          	<windVelocity>${windType}</windVelocity>
			<frontal_area>0.02</frontal_area>
			<lateral_area>0.006</lateral_area>
			<lateral_length>1.06</lateral_length>
	  		<waterVelocity>${waterType}</waterVelocity>
        </buoyancy>
    </link>

    <joint name="front_l_joint" type="revolute">
        <parent link="base_link"/>
        <child link="front_l_link"/>
        <origin rpy="0 0 0" xyz="${1.3*scale} ${0.2*scale} 0"/>
	<limit effort="50" velocity="5" lower="0" upper="0" />
            <dynamics damping="1.0"/>
            <axis xyz="1 0 0"/>
    </joint>
    
    <link name="front_r_link">
    	<visual>
    		<origin rpy="0 0 0"  xyz="0 0 0"/>
          <geometry>
           	<mesh filename="package://usv_sim/meshes/simpleHull3/frontRight.dae" scale="${scale} ${scale} ${scale}"/>
          </geometry>
        </visual>
        <collision>
          <origin rpy="0 0 0"  xyz="${0*scale} ${0*scale} 0"/>
          <geometry>
           	<mesh filename="package://usv_sim/meshes/simpleHull3/frontRight.dae" scale="${scale} ${scale} ${scale}"/>
          </geometry>
        </collision>

        <inertial>
            <origin rpy="0 0 0" xyz="${0.4*scale} 0 ${-0.1*scale}"/>
          <mass value="${front_body_mass}"/>
          <inertia ixx="0.1" ixy="0.0" ixz="0.0" iyy="1.4" iyz="0.0" izz="1.4"/>
        </inertial>
        <buoyancy>
          <compensation>${front_water_displaced_mass/front_body_mass}</compensation>
          <origin xyz="${0.4*scale} 0 ${-0.05*scale}"/>
          <limit radius="0.1"/>
          <damping rpy="${angularDampingXYZ}" xyz="${dampingXYZ}"/>
          <windVelocity>${windType}</windVelocity>
	  	  <waterVelocity>${waterType}</waterVelocity>
	  	  <frontal_area>0.02</frontal_area>
		  <lateral_area>0.006</lateral_area>
		  <lateral_length>1.06</lateral_length>
        </buoyancy>
    </link>

    <joint name="front_r_joint" type="revolute">
        <parent link="base_link"/>
        <child link="front_r_link"/>
        <origin rpy="0 0 0" xyz="${1.3*scale} ${-0.2*scale} 0"/>
	<limit effort="50" velocity="5" lower="0" upper="0" />
            <dynamics damping="1.0"/>
            <axis xyz="1 0 0"/>
    </joint>

    <!-- Thruster link -->
    <xacro:macro name="thruster_link" params="name xyz rpy rotationAxis effort:=50 velocity:=5 lowerLimit upperLimit parentLink:=back_r_link">
        <joint name="${name}_joint" type="revolute">
            <parent link="${parentLink}"/>
            <child link="${name}"/>
            <origin rpy="${rpy}" xyz="${xyz}"/>
            <dynamics damping="1.0"/>
            <axis xyz="${rotationAxis}"/>
            <limit effort="${effort}" velocity="${velocity}" lower="${lowerLimit}" upper="${upperLimit}" />
        </joint>
        
        <link name="${name}">      
	    	<collision>
          		<origin xyz="${-0.15*scale} 0 ${0*scale}" rpy="0 0 0"/>
          		<geometry>
          		    <mesh filename="package://usv_sim/meshes/simpleHull3/thruster.dae" scale="${scale} ${scale} ${scale}"/>
          		</geometry>
        	</collision>

            <visual name="${name}">
                <origin xyz="${-0.15*scale} 0 ${0*scale}" rpy="0 0 0" />
                <geometry>
                    <mesh filename="package://usv_sim/meshes/simpleHull3/thruster.dae" scale="${scale} ${scale} ${scale}"/>
                </geometry>
                <material name="black">
                    <color rgba="255 255 255 1"/>
                </material>
            </visual>  

            <inertial>
                <mass value="0.1"/>
                <origin xyz="${-0.2*scale} 0 ${0.3*scale}" rpy="0 0 0" />
                <inertia
                    ixx=".1"
                    ixy="0.0"
                    ixz="0.0"
                    iyy=".1"
                    iyz="0.0"
                    izz=".1"/>
            </inertial>  
            <buoyancy>
				<compensation>0.8</compensation>
	        	<windVelocity>${windType}</windVelocity>
				<waterVelocity>${waterType}</waterVelocity>
			</buoyancy>
        </link>                 
            
        <gazebo reference="${name}">
            <material>Gazebo/Black</material>
        </gazebo>
    </xacro:macro>                   

    <xacro:macro name="thruster_dummy_link" params="name xyz rpy">        
        <joint name="${name}" type="fixed">
            <parent link="base_link"/>
            <child link="${name}"/>
            <origin rpy="${rpy}" xyz="${xyz}"/>
        </joint>
        <link name="${name}"/>
    </xacro:macro>  
    
    
    <!-- Thruster link -->
    <xacro:macro name="airthruster_link" params="name xyz rpy rotationAxis effort:=100 velocity:=20 lowerLimit upperLimit parentLink:=back_r_link">
        <joint name="${name}_joint" type="revolute">
            <parent link="${parentLink}"/>
            <child link="${name}"/>
            <origin rpy="${rpy}" xyz="${xyz}"/>
            <dynamics damping="10.0"/>
            <axis xyz="${rotationAxis}"/>
            <limit effort="${effort}" velocity="${velocity}" lower="${lowerLimit}" upper="${upperLimit}" />
        </joint>
        
        <link name="${name}">      
	    	<collision>
          		<origin xyz="0 0 0" rpy="0 0 0"/>
          		<geometry>
          			<box size="${bl1} ${bl1} ${bl2}" />
          		</geometry>
        	</collision>

            <visual name="${name}">
                <origin xyz="0 0 0" rpy="0 0 0" />
                
                <geometry>
                    	<mesh filename="package://usv_sim/meshes/simpleHull3/airPropeller.dae" scale="${0.9*scale} ${0.9*scale} ${0.9*scale}"/>
                </geometry>
            </visual>  

            <inertial>
                <mass value=".1"/>
                <inertia
                    ixx=".1"
                    ixy="0.0"
                    ixz="0.0"
                    iyy=".1"
                    iyz="0.0"
                    izz=".1"/>
            </inertial>  
        </link>                 
            
        <gazebo reference="${name}">
            <material>Gazebo/Black</material>
        </gazebo>
    </xacro:macro>                   

    <xacro:macro name="thruster_dummy_link" params="name xyz rpy">        
        <joint name="${name}" type="fixed">
            <parent link="base_link"/>
            <child link="${name}"/>
            <origin rpy="${rpy}" xyz="${xyz}"/>
        </joint>
        <link name="${name}"/>
    </xacro:macro>  

    <!-- Rudder link -->
    <xacro:macro name="rudder_xacro">
        <link name="rudder">
            <inertial>
                <mass value="1" />
                <inertia
                  ixx="0.05"
                  ixy="0.0"
                  iyy="0.05"
                  ixz="0.0"
                  iyz="0.0"
                  izz="0.005"/>
            </inertial>

            <collision name="collision">
                <geometry>
                  <box size="${0.2*scale} ${0.02*scale} ${0.3*scale}" />
                </geometry>
                <origin rpy="0 0 0" xyz="${-0.1*scale} 0 0"/>
            </collision>

            <visual name="visual">
                <geometry>
                
                  <mesh filename="package://usv_sim/meshes/simpleHull3/box.dae" scale="${0.2*scale} ${0.02*scale} ${0.3*scale}"/>
                  
                </geometry>
                <origin rpy="0 0 0" xyz="${-0.1*scale} 0 0"/>
                
            </visual>

        </link>

        <joint name="rudder_joint" type="revolute">
            <parent link="back_r_link"/>
            <child link="rudder"/>
            <origin rpy="0 0 0" xyz="${-1.4*scale} ${0.39*scale} ${-0.5*scale}"/>
            <dynamics damping="1.0"/>
            <axis xyz="0 0 1"/>
            <limit effort="100" velocity="5" lower="-${PI/2}" upper="${PI/2}" />
        </joint>
    </xacro:macro> 

    <!-- Sensors -->

    <!-- Hokuyo Laser -->
    <joint name="hokuyo_joint" type="revolute">
        <axis xyz="0 1 0" />
        <origin xyz="0.50 0 0.15" rpy="0 0 0"/>
        <parent link="base_link"/>
        <child link="hokuyo_link"/>
        <limit effort="100" velocity="5" lower="0" upper="0" />
    </joint>

    <link name="hokuyo_link">
        <collision name="collision">
	        <origin xyz="0 0 0" rpy="0 0 0"/>
	        <geometry>
	        	<box size="0.1 0.1 0.1"/>
	        </geometry>
        </collision>

        <visual name="visual">
        	<origin xyz="0 0 0" rpy="0 0 0"/>
        	<geometry>
        		<mesh filename="package://usv_sim/meshes/simpleHull3/box.dae" scale="0.1 0.1 0.1"/>
        		
        	</geometry>
        	
        </visual>

        <inertial>
        <mass value="1e-5" />
        <origin xyz="0 0 0" rpy="0 0 0"/>
        <inertia ixx="1e-6" ixy="0" ixz="0" iyy="1e-6" iyz="0" izz="1e-6" />
        </inertial>
    </link>

    <gazebo reference="hokuyo_link">
        <sensor type="gpu_ray" name="head_hokuyo_sensor">
        <pose>0 0 0 0 0 0</pose>
        <visualize>false</visualize>
        <update_rate>40</update_rate>
        <ray>
        <scan>
        <horizontal>
        <samples>720</samples>
        <resolution>1</resolution>
        <min_angle>-1.570796</min_angle>
        <max_angle>1.570796</max_angle>
        </horizontal>
        </scan>
        <range>
        <min>0.10</min>
        <max>30.0</max>
        <resolution>0.01</resolution>
        </range>
        <noise>
        <type>gaussian</type>
        <!-- Noise parameters based on published spec for Hokuyo laser
        achieving "+-30mm" accuracy at range < 10m.  A mean of 0.0m and
        stddev of 0.01m will put 99.7% of samples within 0.03m of the true
        reading. -->
        <mean>0.0</mean>
        <stddev>0.01</stddev>
        </noise>
        </ray>
        <plugin name="gazebo_ros_head_hokuyo_controller" filename="libgazebo_ros_gpu_laser.so">
        <topicName>scan</topicName>
        <frameName>base_laser</frameName>
        </plugin>
        </sensor>
    </gazebo>

</xacro>
