<?xml version="1.0"?>
<robot name="girona500">

  <link name="base_link">
    <inertial>
      <mass value="95" />
      <inertia ixx="100"  ixy="0"  ixz="0" iyy="100" iyz="0" izz="100" />
    </inertial>
    <visual>
      <origin rpy="-1.57 0 3.14" xyz="-0.2 0 0.75"/>
      <geometry>
        <mesh filename="robot/GIRONA500/g500_March11.osg"/>
      </geometry>
    </visual>
  </link>

  <link name="part0">
    <visual>
      <origin rpy="0.0 0 0" xyz="0 0 0"/>
      <geometry>
        <mesh filename="robot/ARM5E/ARM5E_part0.osg"/>
      </geometry>
    </visual>
  </link>

  <joint name="baselink_to_part0" type="fixed">
    <parent link="base_link"/>
    <child link="part0"/>
    <origin rpy="3.14 0 3.14" xyz="0 0 0.95"/>
  </joint>

 <link name="part1">
    <visual>
      <origin rpy="0 0 0" xyz="0.0 0 0"/>
      <geometry>
        <mesh filename="robot/ARM5E/ARM5E_part1.osg"/>
      </geometry>
    </visual>
  </link>

  <joint name="Slew" type="continuous">
    <parent link="part0"/>
    <child link="part1"/>
    <axis xyz="0 0 -1"/>
    <origin rpy="0 0 0" xyz="0 0 0"/>
  </joint>

 <link name="part2">
    <visual>
      <origin rpy="0 -0.209 0" xyz="0 0 0"/>
      <geometry>
        <mesh filename="robot/ARM5E/ARM5E_part2.osg"/>
      </geometry>
    </visual>
  </link>

  <joint name="Shoulder" type="continuous">
    <parent link="part1"/>
    <child link="part2"/>
    <axis xyz="0 1 0"/>
    <origin rpy="0 0.209 0" xyz="0.077 0 -0.130"/>
  </joint>

 <link name="part3">
    <visual>
      <origin rpy="0 0 0" xyz="0 0 0"/>
      <geometry>
        <mesh filename="robot/ARM5E/ARM5E_part3.osg"/>
      </geometry>
    </visual>
  </link>

  <joint name="Elbow" type="continuous">
    <parent link="part2"/>
    <child link="part3"/>
    <axis xyz="0 1 0"/>
    <origin rpy=" 0 0.262 0 " xyz="0.44278 0 0"/>
  </joint>

  <link name="part4_base">
    <visual>
      <origin rpy="0 0 0" xyz="0 0 0"/>
      <geometry>
        <mesh filename="robot/ARM5E/ARM5E_part4_base.osg"/>
      </geometry>
    </visual>
  </link>

  <joint name="JawRotate" type="continuous">
    <parent link="part3"/>
    <child link="part4_base"/>
    <axis xyz="1 0 0"/>
    <origin rpy="0 0 0" xyz="0.320 0 0.077 "/>
  </joint>


  <link name="part4_jaw1">
    <visual>
      <origin rpy="0 0 0" xyz="0 0 0"/>
      <geometry>
        <mesh filename="robot/ARM5E/ARM5E_part4_jaw1.osg"/>
      </geometry>
    </visual>
  </link>

  <joint name="JawOpening" type="continuous">
    <parent link="part4_base"/>
    <child link="part4_jaw1"/>
    <axis xyz="0 -1 0"/>
    <origin rpy="0 0 0" xyz="0.07 0 0.04"/>
  </joint>


  <link name="part4_jaw2">
    <visual>
      <origin rpy="0 0 0" xyz="0 0 0"/>
      <geometry>
        <mesh filename="robot/ARM5E/ARM5E_part4_jaw2.osg"/>
      </geometry>
    </visual>
  </link>

  <joint name="part4_to_part4_jaw2" type="continuous">
    <parent link="part4_base"/>
    <child link="part4_jaw2"/>
    <axis xyz="0 1 0"/>
    <origin rpy="0 0 0" xyz="0.07 0 -0.04"/>
    <mimic joint="JawOpening" multiplier="1" offset="0"/>
  </joint>

  <link name="stereo_down_optical"/>

  <joint name="stereo_down_optical_to_part0" type="fixed">
    <parent link="part0"/>
    <child link="stereo_down_optical"/>
    <origin rpy="3.1416 0 1.57" xyz="-0.5 -0.06 0"/>
  </joint>

  <link name="sls"/>

  <joint name="sls_to_part0" type="fixed">
    <parent link="part0"/>
    <child link="sls"/>
    <origin rpy="3.1416 0 1.57" xyz="-0.5 0.1 0"/>
  </joint>

</robot>
