<?xml version="1.0" ?>
<!-- =================================================================================== -->
<!-- |    This document was autogenerated by xacro from g500ARM5.urdf.xacro            | -->
<!-- |    EDITING THIS FILE BY HAND IS NOT RECOMMENDED                                 | -->
<!-- =================================================================================== -->
<robot name="girona500" xmlns:xacro="http://www.ros.org/wiki/xacro">
  <link name="base_link">
    <inertial>
      <mass value="95"/>
      <inertia ixx="100" ixy="0" ixz="0" iyy="100" iyz="0" izz="100"/>
    </inertial>
    <visual>
      <origin rpy="-1.570796327 0 3.141592654" xyz="-0.2 0 0.75"/>
      <geometry>
        <mesh filename="robot/GIRONA500/g500_March11.osg"/>
      </geometry>
    </visual>
  </link>
  <link name="part0">
    <visual>
      <origin rpy="3.141592654 0 0" xyz="0 0 0"/>
      <geometry>
        <mesh filename="robot/ARM5E/ARM5E_part0.osg"/>
      </geometry>
    </visual>
  </link>
  <joint name="baselink_to_part0" type="fixed">
    <parent link="base_link"/>
    <child link="part0"/>
    <origin rpy="0 0 3.141592654" xyz="0 0 0.95"/>
  </joint>
  <link name="kinematic_base">
    <!-- kinematic base of the robot -->
  </link>
  <joint name="part0_to_kinematic_base" type="fixed">
    <parent link="part0"/>
    <child link="kinematic_base"/>
    <origin rpy="0 0 0" xyz="0 0 0.13"/>
  </joint>
  <link name="part1">
    <visual>
      <origin rpy="3.141592654 0 0" xyz="0.0 0 -0.13"/>
      <geometry>
        <mesh filename="robot/ARM5E/ARM5E_part1.osg"/>
      </geometry>
    </visual>
  </link>
  <joint name="Slew" type="continuous">
    <parent link="kinematic_base"/>
    <child link="part1"/>
    <axis xyz="0 0 1"/>
    <origin rpy="0 0 0" xyz="0 0 0"/>
    <!-- La distancia base_link - base cinematica es 1.08. -->
    <limit effort="1000.0" lower="-1.570796327" upper="0.5488" velocity="1.0"/>
  </joint>
  <link name="part2">
    <visual>
      <origin rpy="1.570796327 0 -0.087262726" xyz="0 0 0"/>
      <!-- rpy="1.57 -0.209 0" xyz="0 0 0" -->
      <geometry>
        <mesh filename="robot/ARM5E/ARM5E_part2.osg"/>
      </geometry>
    </visual>
  </link>
  <joint name="Shoulder" type="continuous">
    <parent link="part1"/>
    <child link="part2"/>
    <axis xyz="0 0 1"/>
    <origin rpy="1.570796327 0 0" xyz="0.08052 0 0"/>
    <limit effort="1000.0" lower="0" upper="1.58665" velocity="1.0"/>
  </joint>
  <link name="part3">
    <visual>
      <origin rpy="1.570796327 0 0.4014" xyz="0 0 0"/>
      <geometry>
        <mesh filename="robot/ARM5E/ARM5E_part3.osg"/>
      </geometry>
    </visual>
  </link>
  <joint name="Elbow" type="continuous">
    <parent link="part2"/>
    <child link="part3"/>
    <axis xyz="0 0 1"/>
    <origin rpy="0 0 0.139277274" xyz="0.438492379277 0.0614700067987 0"/>
    <limit effort="1000.0" lower="0" upper="2.15294" velocity="1.0"/>
  </joint>
  <link name="part4_base">
    <visual>
      <origin rpy="0 -1.570796327 0" xyz="0 0 -0.028"/>
      <!-- TEMPORAL: para compensar la pieza que falta -->
      <geometry>
        <mesh filename="robot/ARM5E/ARM5E_part4_base.osg"/>
      </geometry>
    </visual>
  </link>
  <joint name="JawRotate" type="continuous">
    <parent link="part3"/>
    <child link="part4_base"/>
    <axis xyz="0 0 1"/>
    <origin rpy="1.570796327 0 1.972222055" xyz="0.349117258152 0.058023572508 0"/>
  </joint>
  <link name="end_effector">
    <!-- From the kinematic base of the robot -->
  </link>
  <joint name="part4_base_to_end_effector" type="fixed">
    <parent link="part4_base"/>
    <child link="end_effector"/>
    <origin rpy="0 0 0" xyz="0 0 0.1485"/>
  </joint>
  <link name="part4_jaw1">
    <visual>
      <origin rpy="0 -1.570796327 0" xyz="0 0 0"/>
      <geometry>
        <mesh filename="robot/ARM5E/ARM5E_part4_jaw1.osg"/>
      </geometry>
    </visual>
  </link>
  <joint name="JawOpening" type="continuous">
    <parent link="part4_base"/>
    <child link="part4_jaw1"/>
    <axis xyz="0 -1 0"/>
    <origin rpy="0 0 0" xyz="-0.04 0 0.045"/>
    <!-- x era 0.07-->
    <limit effort="1000.0" lower="-0.05816" upper="1.337696" velocity="1.0"/>
  </joint>
  <link name="part4_jaw2">
    <visual>
      <origin rpy="0 -1.570796327 0" xyz="0 0 0"/>
      <geometry>
        <mesh filename="robot/ARM5E/ARM5E_part4_jaw2.osg"/>
      </geometry>
    </visual>
  </link>
  <joint name="part4_to_link4_jaw2" type="continuous">
    <parent link="part4_base"/>
    <child link="part4_jaw2"/>
    <axis xyz="0 1 0"/>
    <origin rpy="0 0 0" xyz="0.04 0 0.0450"/>
    <!-- x era 0.07-->
    <mimic joint="JawOpening" multiplier="1" offset="0"/>
  </joint>
</robot>

