<?xml version="1.0" ?>
<!-- =================================================================================== -->
<!-- |    This document was autogenerated by xacro from barco_obs.xacro                | -->
<!-- |    EDITING THIS FILE BY HAND IS NOT RECOMMENDED                                 | -->
<!-- =================================================================================== -->
<!-- STL-version of the URDF, used with gazebo for dynamic simulation  -->
<robot name="barco_obs" xmlns:xacro="http://www.ros.org/wiki/xacro">
  <link name="base_link">
    <collision>
      <origin rpy="1.57079632679 0 0"/>
      <geometry>
        <box size="5 1 5"/>
      </geometry>
    </collision>
    <visual>
      <origin rpy="1.57079632679 0 0"/>
      <geometry>
        <box size="5 1 5"/>
      </geometry>
      <material name="blue"/>
    </visual>
    <inertial>
      <origin rpy="0 0 0" xyz="0 0 0"/>
      <mass value="10"/>
      <inertia ixx="3" ixy="0.0" ixz="0.0" iyy="1" iyz="0.0" izz="3"/>
    </inertial>
    <buoyancy>
      <compensation>1.2</compensation>
      <origin xyz="0 0 0"/>
      <limit radius="0.2"/>
      <damping rpy="20 50 50" xyz="20 50 50"/>
    </buoyancy>
  </link>
  <link name="side_link1">
    <collision>
      <origin rpy="1.57079632679 0 0"/>
      <geometry>
        <box size="30 0.5 0.5"/>
      </geometry>
    </collision>
    <visual>
      <origin rpy="1.57079632679 0 0" xyz="0 -9 0"/>
      <geometry>
        <box size="30 0.5 0.5"/>
      </geometry>
      <material name="blue"/>
    </visual>
    <inertial>
      <origin rpy="0 0 0" xyz="0 -9 0"/>
      <mass value="10"/>
      <inertia ixx="3" ixy="0.0" ixz="0.0" iyy="1" iyz="0.0" izz="3"/>
    </inertial>
    <buoyancy>
      <compensation>1.2</compensation>
      <origin xyz="0 0 0"/>
      <limit radius="0.2"/>
      <damping rpy="20 50 50" xyz="20 50 50"/>
    </buoyancy>
  </link>
  <link name="side_link2">
    <collision>
      <origin rpy="1.57079632679 0 0"/>
      <geometry>
        <box size="30 0.5 0.5"/>
      </geometry>
    </collision>
    <visual>
      <origin rpy="1.57079632679 0 0" xyz="0 9 0"/>
      <geometry>
        <box size="30 0.5 0.5"/>
      </geometry>
      <material name="blue"/>
    </visual>
    <inertial>
      <origin rpy="0 0 0" xyz="0 9 0"/>
      <mass value="10"/>
      <inertia ixx="3" ixy="0.0" ixz="0.0" iyy="1" iyz="0.0" izz="3"/>
    </inertial>
    <buoyancy>
      <compensation>1.2</compensation>
      <origin xyz="0 0 0"/>
      <limit radius="0.2"/>
      <damping rpy="20 50 50" xyz="20 50 50"/>
    </buoyancy>
  </link>
  <joint name="side_joint1" type="revolute">
    <parent link="base_link"/>
    <child link="side_link1"/>
    <origin rpy="0 0 0" xyz="-0.53 0 -0.1"/>
    <dynamics damping="1.0"/>
    <axis xyz="0 0 1"/>
    <limit effort="50" lower="-1.0471975512" upper="1.0471975512" velocity="5"/>
  </joint>
  <joint name="side_joint2" type="revolute">
    <parent link="base_link"/>
    <child link="side_link2"/>
    <origin rpy="0 0 0" xyz="-0.53 0 -0.1"/>
    <dynamics damping="1.0"/>
    <axis xyz="0 0 1"/>
    <limit effort="50" lower="-1.0471975512" upper="1.0471975512" velocity="5"/>
  </joint>
</robot>
