<?xml version="1.0" ?>
<!-- =================================================================================== -->
<!-- |    This document was autogenerated by xacro from boat_diff.xacro                | -->
<!-- |    EDITING THIS FILE BY HAND IS NOT RECOMMENDED                                 | -->
<!-- =================================================================================== -->
<robot name="boat_diff" xmlns:xacro="http://www.ros.org/wiki/xacro">
  <link name="base_link">
    <visual>
      <origin rpy="1.57079632679 0 1.57079632679"/>
      <geometry>
        <mesh filename="package://usv_sim/meshes/pt90.stl"/>
      </geometry>
      <material name="blue"/>
    </visual>
    <inertial>
      <origin rpy="0 0 0" xyz="0 0 -0.05"/>
      <mass value="10"/>
      <inertia ixx="0.1" ixy="0.0" ixz="0.0" iyy="1.4" iyz="0.0" izz="1.4"/>
    </inertial>
    <buoyancy>
      <compensation>1.2</compensation>
      <origin xyz="-0.0005 0 0.05"/>
      <limit radius="0.1"/>
      <damping rpy="20 50 50" xyz="20 50 50"/>
    </buoyancy>
  </link>
  <!-- Sensors -->
  <!-- Hokuyo Laser -->
  <joint name="hokuyo_joint" type="fixed">
    <axis xyz="0 1 0"/>
    <origin rpy="0 0 0" xyz="0.6 0 0.1"/>
    <parent link="base_link"/>
    <child link="hokuyo_link"/>
  </joint>
  <link name="hokuyo_link">
    <collision>
      <origin rpy="0 0 0" xyz="0 0 0"/>
      <geometry>
        <box size="0.1 0.1 0.1"/>
      </geometry>
    </collision>
    <visual>
      <origin rpy="0 0 0" xyz="0 0 0"/>
      <geometry>
        <mesh filename="package://usv_sim/meshes/hokuyo.dae"/>
      </geometry>
    </visual>
    <inertial>
      <mass value="1e-5"/>
      <origin rpy="0 0 0" xyz="0 0 0"/>
      <inertia ixx="1e-6" ixy="0" ixz="0" iyy="1e-6" iyz="0" izz="1e-6"/>
    </inertial>
  </link>
  <gazebo reference="hokuyo_link">
    <sensor name="head_hokuyo_sensor" type="gpu_ray">
      <pose>0 0 0 0 0 0</pose>
      <visualize>true</visualize>
      <update_rate>40</update_rate>
      <ray>
        <scan>
          <horizontal>
            <samples>720</samples>
            <resolution>1</resolution>
            <min_angle>-1.570796</min_angle>
            <max_angle>1.570796</max_angle>
          </horizontal>
        </scan>
        <range>
          <min>0.10</min>
          <max>30.0</max>
          <resolution>0.01</resolution>
        </range>
        <noise>
          <type>gaussian</type>
          <!-- Noise parameters based on published spec for Hokuyo laser
        achieving "+-30mm" accuracy at range < 10m.  A mean of 0.0m and
        stddev of 0.01m will put 99.7% of samples within 0.03m of the true
        reading. -->
          <mean>0.0</mean>
          <stddev>0.01</stddev>
        </noise>
      </ray>
      <plugin filename="libgazebo_ros_gpu_laser.so" name="gazebo_ros_head_hokuyo_controller">
        <topicName>scan</topicName>
        <frameName>base_laser</frameName>
      </plugin>
    </sensor>
  </gazebo>
  <!-- Plugin list -->
  <gazebo>
    <plugin filename="libfreefloating_gazebo_control.so" name="freefloating_gazebo_control">
      <switchService>switch</switchService>
      <updateRate>100</updateRate>
      <link>base_link</link>
      <thruster>
        <effort>30</effort>
        <name>fwd_left</name>
      </thruster>
      <thruster>
        <effort>30</effort>
        <name>fwd_right</name>
      </thruster>
    </plugin>
  </gazebo>
  <joint name="fwd_left_link" type="revolute">
    <parent link="base_link"/>
    <child link="fwd_left"/>
    <origin rpy="0 -1.57079632679 0" xyz="-0.52 0.1 0"/>
    <dynamics damping="10.0"/>
    <axis xyz="0 1 0"/>
    <limit effort="30" lower="-1.57079632679" upper="1.57079632679" velocity="5.0"/>
  </joint>
  <link name="fwd_left">
    <buoyancy>
      <compensation>1.0</compensation>
    </buoyancy>
    <visual name="fwd_left_1">
      <geometry>
        <cylinder length="0.1" radius="0.02"/>
      </geometry>
      <material name="black">
        <color rgba="0 0 0 1"/>
      </material>
    </visual>
    <visual name="fwd_left_2">
      <origin xyz="0 0 0.065"/>
      <geometry>
        <cylinder length="0.03" radius="0.05"/>
      </geometry>
      <material name="black">
        <color rgba="0 0 0 1"/>
      </material>
    </visual>
    <inertial>
      <mass value=".1"/>
      <inertia ixx=".1" ixy="0.0" ixz="0.0" iyy=".1" iyz="0.0" izz=".1"/>
    </inertial>
  </link>
  <gazebo reference="fwd_left">
    <material>Gazebo/Black</material>
  </gazebo>
  <joint name="fwd_right_link" type="revolute">
    <parent link="base_link"/>
    <child link="fwd_right"/>
    <origin rpy="0 -1.57079632679 0" xyz="-0.52 -0.1 0"/>
    <dynamics damping="10.0"/>
    <axis xyz="0 1 0"/>
    <limit effort="30" lower="-1.57079632679" upper="1.57079632679" velocity="5.0"/>
  </joint>
  <link name="fwd_right">
    <buoyancy>
      <compensation>1.0</compensation>
    </buoyancy>
    <visual name="fwd_right_1">
      <geometry>
        <cylinder length="0.1" radius="0.02"/>
      </geometry>
      <material name="black">
        <color rgba="0 0 0 1"/>
      </material>
    </visual>
    <visual name="fwd_right_2">
      <origin xyz="0 0 0.065"/>
      <geometry>
        <cylinder length="0.03" radius="0.05"/>
      </geometry>
      <material name="black">
        <color rgba="0 0 0 1"/>
      </material>
    </visual>
    <inertial>
      <mass value=".1"/>
      <inertia ixx=".1" ixy="0.0" ixz="0.0" iyy=".1" iyz="0.0" izz=".1"/>
    </inertial>
  </link>
  <gazebo reference="fwd_right">
    <material>Gazebo/Black</material>
  </gazebo>
</robot>

