<?xml version="1.0" ?>
<!-- =================================================================================== -->
<!-- |    This document was autogenerated by xacro from g500arm5e.xacro                | -->
<!-- |    EDITING THIS FILE BY HAND IS NOT RECOMMENDED                                 | -->
<!-- =================================================================================== -->
<robot name="g500arm5e" xmlns:xacro="http://www.ros.org/wiki/xacro">
  <gazebo>
    <!-- Gazebo plugin listens to the body-->
    <plugin filename="libfreefloating_gazebo_control.so" name="freefloating_gazebo_control">
      <switchService>switch</switchService>
      <updateRate>100</updateRate>
      <link>base_link</link>
      <bodyCommandTopic>body_command</bodyCommandTopic>
      <jointCommandTopic>joint_command</jointCommandTopic>
      <!-- for each thruster, give the map to XYZ+RPY and the maximum effort -->
      <thruster>
        <map>-1 0 0 0 0 -0.35</map>
        <effort>30</effort>
      </thruster>
      <thruster>
        <map>-1 0 0 0 0 0.35</map>
        <effort>30</effort>
      </thruster>
      <thruster>
        <map>0 1 0 0 0 0</map>
        <effort>30</effort>
      </thruster>
      <thruster>
        <map>0 0 -1 0 0 0</map>
        <effort>30</effort>
      </thruster>
      <thruster>
        <map>0 0 -1 0 1.1 0</map>
        <effort>30</effort>
      </thruster>
    </plugin>
  </gazebo>
  <link name="base_link">
    <visual>
      <origin rpy="-1.57079632679 0 3.14159265359" xyz="-0.2 0 0.75"/>
      <geometry>
        <mesh filename="file:///home/olivier/.uwsim/data/robot/GIRONA500/g500_March11.stl"/>
      </geometry>
    </visual>
    <inertial>
      <origin rpy="0 0 0" xyz="-0.55 0 0.35"/>
      <mass value="100.0"/>
      <inertia ixx="19.22" ixy="0.0" ixz="0.0" iyy="31.4225" iyz="-6.125" izz="25.2975"/>
    </inertial>
    <!--collision>
      <origin xyz="0 0 0" rpy="0 0 0"/>
      <geometry>
	<box size="1 1 1"/>
      </geometry>
    </collision-->
    <buoyancy>
      <compensation>1.01</compensation>
      <origin xyz="-0.55 0 0.175"/>
      <limit radius=".5"/>
      <damping xyz="60 100 100"/>
    </buoyancy>
  </link>
  <link name="part0">
    <visual>
      <origin rpy="0.0 0 0" xyz="0 0 0"/>
      <geometry>
        <mesh filename="file:///home/olivier/.uwsim/data/robot/ARM5E/ARM5E_part0.dae"/>
      </geometry>
    </visual>
    <inertial>
      <origin rpy="0 0 0" xyz="0 0 0"/>
      <mass value="1"/>
      <inertia ixx="0.004" ixy="0.0" ixz="0.0" iyy="0.004" iyz="0.0" izz="0.004"/>
    </inertial>
    <buoyancy>
      <compensation>1.0</compensation>
    </buoyancy>
  </link>
  <joint name="baselink_to_part0" type="fixed">
    <parent link="base_link"/>
    <child link="part0"/>
    <origin rpy="3.14 0 3.14" xyz="0 0 0.95"/>
  </joint>
  <link name="part1">
    <visual>
      <origin rpy="0 0 0" xyz="0.0 0 0"/>
      <geometry>
        <mesh filename="file:///home/olivier/.uwsim/data/robot/ARM5E/ARM5E_part1.dae"/>
      </geometry>
    </visual>
    <inertial>
      <origin rpy="0 0 0" xyz="0 0 0"/>
      <mass value="1"/>
      <inertia ixx="0.004" ixy="0.0" ixz="0.0" iyy="0.004" iyz="0.0" izz="0.004"/>
    </inertial>
    <buoyancy>
      <compensation>1.0</compensation>
    </buoyancy>
  </link>
  <joint name="Slew" type="revolute">
    <parent link="part0"/>
    <child link="part1"/>
    <axis xyz="0 0 -1"/>
    <origin rpy="0 0 0" xyz="0 0 0"/>
    <dynamics damping="0.8"/>
    <limit effort="500" lower="-1.57079632679" upper="1.57079632679" velocity="1"/>
  </joint>
  <link name="part2">
    <visual>
      <origin rpy="0 -0.209 0" xyz="0 0 0"/>
      <geometry>
        <mesh filename="file:///home/olivier/.uwsim/data/robot/ARM5E/ARM5E_part2.dae"/>
      </geometry>
    </visual>
    <inertial>
      <origin rpy="0 0 0" xyz="0 0 0"/>
      <mass value="1"/>
      <inertia ixx="0.004" ixy="0.0" ixz="0.0" iyy="0.004" iyz="0.0" izz="0.004"/>
    </inertial>
    <buoyancy>
      <compensation>1.0</compensation>
    </buoyancy>
  </link>
  <joint name="Shoulder" type="revolute">
    <parent link="part1"/>
    <child link="part2"/>
    <axis xyz="0 1 0"/>
    <origin rpy="0 0.209 0" xyz="0.077 0 -0.130"/>
    <dynamics damping="0.8"/>
    <limit effort="500" lower="0" upper="1.57079632679" velocity="1"/>
  </joint>
  <link name="part3">
    <visual>
      <origin rpy="0 0 0" xyz="0 0 0"/>
      <geometry>
        <mesh filename="file:///home/olivier/.uwsim/data/robot/ARM5E/ARM5E_part3.dae"/>
      </geometry>
    </visual>
    <inertial>
      <origin rpy="0 0 0" xyz="0 0 0"/>
      <mass value="1"/>
      <inertia ixx="0.004" ixy="0.0" ixz="0.0" iyy="0.004" iyz="0.0" izz="0.004"/>
    </inertial>
    <buoyancy>
      <compensation>1.0</compensation>
    </buoyancy>
  </link>
  <joint name="Elbow" type="revolute">
    <parent link="part2"/>
    <child link="part3"/>
    <axis xyz="0 1 0"/>
    <origin rpy=" 0 0.262 0 " xyz="0.44278 0 0"/>
    <dynamics damping="0.8"/>
    <limit effort="500" lower="0.314159265359" upper="1.57079632679" velocity="1"/>
  </joint>
  <link name="part4_base">
    <visual>
      <origin rpy="0 0 0" xyz="0 0 0"/>
      <geometry>
        <mesh filename="file:///home/olivier/.uwsim/data/robot/ARM5E/ARM5E_part4_base.dae"/>
      </geometry>
    </visual>
    <inertial>
      <origin rpy="0 0 0" xyz="0 0 0"/>
      <mass value="0.1"/>
      <inertia ixx="0.0001" ixy="0.0" ixz="0.0" iyy="0.0001" iyz="0.0" izz="0.0001"/>
    </inertial>
    <buoyancy>
      <compensation>1.0</compensation>
    </buoyancy>
  </link>
  <joint name="JawRotate" type="fixed">
    <parent link="part3"/>
    <child link="part4_base"/>
    <axis xyz="1 0 0"/>
    <origin rpy="0 0 0" xyz="0.320 0 0.077 "/>
  </joint>
  <link name="part5">
    <visual>
      <origin rpy="0 0 0" xyz="0 0 0"/>
      <geometry>
        <cylinder length="0.08" radius="0.01"/>
      </geometry>
      <material name="orange"/>
    </visual>
    <collision>
      <origin rpy="0 0 0" xyz="0 0 0"/>
      <geometry>
        <cylinder length="0.08" radius="0.01"/>
      </geometry>
    </collision>
    <inertial>
      <origin rpy="0 0 0" xyz="0 0 0.03"/>
      <mass value="0.05"/>
      <inertia ixx="1.625e-05" ixy="0.0" ixz="0.0" iyy="1.625e-05" iyz="0.0" izz="2.5e-06"/>
    </inertial>
  </link>
  <joint name="part4_to_5" type="fixed">
    <parent link="part4_base"/>
    <child link="part5"/>
    <origin rpy="0 1.57079632679 0" xyz=".12 0 0 "/>
  </joint>
  <link name="part6">
    <visual>
      <origin rpy="0 0 0" xyz="0 0 .03"/>
      <geometry>
        <cylinder length="0.06" radius="0.008"/>
      </geometry>
    </visual>
    <collision>
      <origin rpy="0 0 0" xyz="0 0 .03"/>
      <geometry>
        <cylinder length="0.06" radius="0.008"/>
      </geometry>
    </collision>
    <inertial>
      <origin rpy="0 0 0" xyz="0 0 0.03"/>
      <mass value="0.05"/>
      <inertia ixx="1.625e-05" ixy="0.0" ixz="0.0" iyy="1.625e-05" iyz="0.0" izz="2.5e-06"/>
    </inertial>
  </link>
  <joint name="part5_to_6" type="fixed">
    <parent link="part5"/>
    <child link="part6"/>
    <origin rpy="0 .6 0" xyz="0 .0 .035 "/>
  </joint>
  <link name="part7">
    <visual>
      <origin rpy="0 0 0" xyz="0 0 .03"/>
      <geometry>
        <cylinder length="0.06" radius="0.006"/>
      </geometry>
    </visual>
    <collision>
      <origin rpy="0 0 0" xyz="0 0 .03"/>
      <geometry>
        <cylinder length="0.06" radius="0.006"/>
      </geometry>
    </collision>
    <inertial>
      <origin rpy="0 0 0" xyz="0 0 0.03"/>
      <mass value="0.05"/>
      <inertia ixx="1.625e-05" ixy="0.0" ixz="0.0" iyy="1.625e-05" iyz="0.0" izz="2.5e-06"/>
    </inertial>
  </link>
  <joint name="part6_to_7" type="fixed">
    <parent link="part6"/>
    <child link="part7"/>
    <origin rpy="0 .6 0" xyz="0 .0 .06 "/>
  </joint>
</robot>

