<?xml version="1.0" ?>
<!-- =================================================================================== -->
<!-- |    This document was autogenerated by xacro from barcoLeme.xacro                | -->
<!-- |    EDITING THIS FILE BY HAND IS NOT RECOMMENDED                                 | -->
<!-- =================================================================================== -->
<robot name="barco_auv" xmlns:xacro="http://www.ros.org/wiki/xacro">
  <link name="base_link">
    <visual>
      <origin rpy="1.57079632679 0 1.57079632679"/>
      <geometry>
        <mesh filename="file:///home/lsa/.uwsim/data/robot/barco/pt90.stl"/>
      </geometry>
      <material name="blue"/>
    </visual>
    <inertial>
        <origin rpy="0 0 0" xyz="0 0 -0.05"/>
      <mass value="10"/>
      <inertia ixx="0.1" ixy="0.0" ixz="0.0" iyy="1.4" iyz="0.0" izz="1.4"/>
    </inertial>
    <buoyancy>
      <compensation>1.2</compensation>
      <origin xyz="-0.0005 0 0.05"/>
      <limit radius="0.1"/>
      <damping rpy="20 50 50" xyz="20 50 50"/>
    </buoyancy>
  </link>
  <link name="rudder">
    <inertial>
      <origin rpy="0 0 0" xyz="-0.1 0 0"/>
      <mass value="0.05"/>
      <inertia ixx="0.1" ixy="0.0" ixz="0.0" iyy="0.01" iyz="0.0" izz="0.05"/>
    </inertial>
    <collision name="collision">
      <geometry>
        <box size="0.1 0.02 0.3"/>
      </geometry>
      <origin rpy="0 0 0" xyz="-0.1 0 0"/>
    </collision>
    <visual name="visual">
      <geometry>
        <box size="0.1 0.02 0.3"/>
      </geometry>
      <origin rpy="0 0 0" xyz="-0.1 0 0"/>
    </visual>
  </link>
  <joint name="rudder_joint" type="revolute">
    <parent link="base_link"/>
    <child link="rudder"/>
    <origin rpy="0 0 0" xyz="-0.53 0 -0.1"/>
    <dynamics damping="1.0"/>
    <axis xyz="0 0 1"/>
    <limit effort="50" lower="-1.0471975512" upper="1.0471975512" velocity="5"/>
  </joint>
  <!-- Plugin list -->
  <gazebo>
    <!-- Gazebo plugin listens to the body-->
    <plugin filename="libLiftDragPlugin.so" name="LiftDrag">
      <!--<plugin name="LiftDrag" filename="libliftdragww.so">-->
      <a0>0</a0>
      <cla>4.752798721</cla>
      <cda>0.6417112299</cda>
      <cma>-1.8</cma>
      <alpha_stall>0.785</alpha_stall>
      <cla_stall>-3.85</cla_stall>
      <cda_stall>-0.9233984055</cda_stall>
      <cma_stall>0</cma_stall>
      <cp>-0.5 0 0</cp>
      <area>0.03</area>
      <air_density>1000</air_density>
      <forward>1 0 0</forward>
      <upward>0 1 0</upward>
      <link_name>rudder</link_name>
    </plugin>
    <plugin filename="libfreefloating_gazebo_control.so" name="freefloating_gazebo_control">
      <switchService>switch</switchService>
      <updateRate>100</updateRate>
      <link>base_link</link>
      <!--    these two thrusters are actually orientable, so the map should not be hard-coded 
                        the thruster name is the name of the corresponding link -->
      <thruster>
        <effort>30</effort>
        <name>fwd</name>
      </thruster>
      <!-- these thrusters are fixed and the map can be hard-coded 
                     they will be given a name (thr2 to thr4)  -->
    </plugin>
  </gazebo>
  <joint name="fwd_link" type="revolute">
    <parent link="base_link"/>
    <child link="fwd"/>
    <origin rpy="0 -1.57079632679 0" xyz="-0.52 0 -0.03"/>
    <dynamics damping="10.0"/>
    <axis xyz="0 1 0"/>
    <limit effort="30" lower="-1.57079632679" upper="1.57079632679" velocity="5.0"/>
  </joint>
  <link name="fwd">
    <buoyancy>
      <compensation>1.0</compensation>
    </buoyancy>
    <visual name="fwd_1">
      <geometry>
        <cylinder length="0.1" radius="0.02"/>
      </geometry>
      <material name="black">
        <color rgba="0 0 0 1"/>
      </material>
    </visual>
    <visual name="fwd_2">
      <origin xyz="0 0 0.065"/>
      <geometry>
        <cylinder length="0.03" radius="0.05"/>
      </geometry>
      <material name="black">
        <color rgba="0 0 0 1"/>
      </material>
    </visual>
    <inertial>
      <mass value="0.01"/>
      <inertia ixx="0.01" ixy="0.0" ixz="0.0" iyy="0.01" iyz="0.0" izz="0.01"/>
    </inertial>
  </link>
  <gazebo reference="fwd">
    <material>Gazebo/Black</material>
  </gazebo>
  <!-- Dummy links to display wrench in Rviz, autogenerated -->
  <!-- <xacro:thruster_dummy_link name="thr2" xyz="0.0 0.0 0.0" rpy="1.57079632679 -0.0 0.0"/>
    <xacro:thruster_dummy_link name="thr3" xyz="-0.45 0.0 0.0" rpy="0.0 -0.0 0.0"/>
    <xacro:thruster_dummy_link name="thr4" xyz="0.45 0.0 0.0" rpy="0.0 -0.0 0.0"/>-->
</robot>

